<?xml version="1.0"?>
<robot name="sixrobot_anno" xmlns:xacro="http://www.ros.org/wiki/xacro">

  <xacro:property name="M_PI" value="3.1415926536"/>
  <xacro:include filename="$(find sixrobot_description)/urdf/materials.urdf.xacro" />
  <xacro:include filename="$(find sixrobot_description)/urdf/gripper.xacro" />

  <link name="world"/>
  <joint name="joint0" type="fixed">
    <origin xyz="0 0 0" rpy="0 0 0" />
    <parent link="world"/>
    <child link="base_link"/>
  </joint>
  <link
    name="base_link">
    <inertial>
      <origin
        xyz="-0.00014183 0.02417 0.019908"
        rpy="0 0 0" />
      <mass
        value="0.00001" />
      <inertia
        ixx="10" ixy="0.0" ixz="0.0" iyy="10" iyz="0.0" izz="10" />
    </inertial>
    <visual>
      <origin
        xyz="0 0 0"
        rpy="0 0 0" />
      <geometry>
        <mesh
          filename="package://sixrobot_description/meshes/base_link.stl" />
      </geometry>
      <material
        name="">
        <color
          rgba="255 250 250 1" />
      </material>
    </visual>
    <collision>
      <origin
        xyz="0 0 0"
        rpy="0 0 0" />
      <geometry>
        <mesh
          filename="package://sixrobot_description/meshes/base_link.stl" />
      </geometry>
    </collision>
  </link>
  <link
    name="Link1">
    <inertial>
      <origin
        xyz="-0.003411 0.071928 -0.0017952"
        rpy="0 0 0" />
      <mass
        value="0.00001" />
      <inertia
        ixx="10" ixy="0.0" ixz="0.0" iyy="10" iyz="0.0" izz="10" />
    </inertial>
    <visual>
      <origin
        xyz="0 0 0"
        rpy="0 0 0" />
      <geometry>
        <mesh
          filename="package://sixrobot_description/meshes/Link1.stl" />
      </geometry>
      <material
        name="">
        <color
          rgba="255 0 0 1" />
      </material>
    </visual>
    <collision>
      <origin
        xyz="0 0 0"
        rpy="0 0 0" />
      <geometry>
        <mesh
          filename="package://sixrobot_description/meshes/Link1.stl" />
      </geometry>
    </collision>
  </link>
  <joint
    name="joint1"
    type="revolute">
    <origin
      xyz="0.00021336 -0.024174 0.09434"
      rpy="1.5708 6.123E-17 1.5708" />
    <parent
      link="base_link" />
    <child
      link="Link1" />
    <axis
      xyz="0 1 0" />
    <limit
      lower="-1.5708"
      upper="1.5708"
      effort="100"
      velocity="1" />
  </joint>
  <link
    name="Link2">
    <inertial>
      <origin
        xyz="0.14201 -8.8611E-08 -0.00098855"
        rpy="0 0 0" />
      <mass
        value="0.00001" />
      <inertia
        ixx="10" ixy="0.0" ixz="0.0" iyy="10" iyz="0.0" izz="10" />
    </inertial>
    <visual>
      <origin
        xyz="0 0 0"
        rpy="0 0 0" />
      <geometry>
        <mesh
          filename="package://sixrobot_description/meshes/Link2.stl" />
      </geometry>
      <material
        name="">
        <color
          rgba="0 255 0 1" />
      </material>
    </visual>
    <collision>
      <origin
        xyz="0 0 0"
        rpy="0 0 0" />
      <geometry>
        <mesh
          filename="package://sixrobot_description/meshes/Link2.stl" />
      </geometry>
    </collision>
  </link>
  <joint
    name="joint2"
    type="revolute">
    <origin
      xyz="-0.005 0.1 0"
      rpy="3.1416 -5.0415E-16 1.5708" />
    <parent
      link="Link1" />
    <child
      link="Link2" />
    <axis
      xyz="0 0 -1" />
    <limit
      lower="-1.5708"
      upper="1.5708"
      effort="100"
      velocity="1" />
  </joint>
  <link
    name="Link3">
    <inertial>
      <origin
        xyz="-0.089574 0.0018335 0.00017688"
        rpy="0 0 0" />
      <mass
        value="0.00001" />
      <inertia
        ixx="10" ixy="0.0" ixz="0.0" iyy="10" iyz="0.0" izz="10" />
    </inertial>
    <visual>
      <origin
        xyz="0 0 0"
        rpy="0 0 0" />
      <geometry>
        <mesh
          filename="package://sixrobot_description/meshes/Link3.stl" />
      </geometry>
      <material
        name="">
        <color
          rgba="0 0 255 1" />
      </material>
    </visual>
    <collision>
      <origin
        xyz="0 0 0"
        rpy="0 0 0" />
      <geometry>
        <mesh
          filename="package://sixrobot_description/meshes/Link3.stl" />
      </geometry>
    </collision>
  </link>
  <joint
    name="joint3"
    type="revolute">
    <origin
      xyz="0.205 0 0"
      rpy="2.2226E-16 1.2197E-16 3.1416" />
    <parent
      link="Link2" />
    <child
      link="Link3" />
    <axis
      xyz="0 0 -1" />
    <limit
      lower="-1.5708"
      upper="1.5708"
      effort="100"
      velocity="1" />
  </joint>
  <link
    name="Link4">
    <inertial>
      <origin
        xyz="0.16084 0.02072 0.028418"
        rpy="0 0 0" />
      <mass
        value="0.00001" />
      <inertia
        ixx="10" ixy="0.0" ixz="0.0" iyy="10" iyz="0.0" izz="10" />
    </inertial>
    <visual>
      <origin
        xyz="0 0 0"
        rpy="0 0 0" />
      <geometry>
        <mesh
          filename="package://sixrobot_description/meshes/Link4.stl" />
      </geometry>
      <material
        name="">
        <color
          rgba="255 0 0 1" />
      </material>
    </visual>
    <collision>
      <origin
        xyz="0 0 0"
        rpy="0 0 0" />
      <geometry>
        <mesh
          filename="package://sixrobot_description/meshes/Link4.stl" />
      </geometry>
    </collision>
  </link>
  <joint
    name="joint4"
    type="revolute">
    <origin
      xyz="-0.11 0.0057828 0"
      rpy="-0.13967 0.1538 1.4216" />
    <parent
      link="Link3" />
    <child
      link="Link4" />
    <axis
      xyz="0.97722 0.12611 0.17071" />
    <limit
      lower="-1.5708"
      upper="1.5708"
      effort="100"
      velocity="1" />
  </joint>
  <link
    name="Link5">
    <inertial>
      <origin
        xyz="-0.088587 5.1035E-09 0.00082307"
        rpy="0 0 0" />
      <mass
        value="0.00001" />
      <inertia
        ixx="10" ixy="0.0" ixz="0.0" iyy="10" iyz="0.0" izz="10" />
    </inertial>
    <visual>
      <origin
        xyz="0 0 0"
        rpy="0 0 0" />
      <geometry>
        <mesh
          filename="package://sixrobot_description/meshes/Link5.stl" />
      </geometry>
      <material
        name="">
        <color
          rgba="0 255 0 1" />
      </material>
    </visual>
    <collision>
      <origin
        xyz="0 0 0"
        rpy="0 0 0" />
      <geometry>
        <mesh
          filename="package://sixrobot_description/meshes/Link5.stl" />
      </geometry>
    </collision>
  </link>
  <joint
    name="joint5"
    type="revolute">
    <origin
      xyz="0.19712 0.025439 0.034436"
      rpy="-0.11711 0.17155 -3.0132" />
    <parent
      link="Link4" />
    <child
      link="Link5" />
    <axis
      xyz="0 0 -1" />
    <limit
      lower="-1.5708"
      upper="1.5708"
      effort="100"
      velocity="1" />
  </joint>
  <link
    name="Link6">
    <inertial>
      <origin
        xyz="-0.020317 9.8259E-07 -2.6983E-07"
        rpy="0 0 0" />
      <mass
        value="0.00001" />
      <inertia
        ixx="10" ixy="0.0" ixz="0.0" iyy="10" iyz="0.0" izz="10" />
    </inertial>
    <visual>
      <origin
        xyz="0 0 0"
        rpy="0 0 0" />
      <geometry>
        <mesh
          filename="package://sixrobot_description/meshes/Link6.stl" />
      </geometry>
      <material
        name="">
        <color
          rgba="0 0 255 1" />
      </material>
    </visual>
    <collision>
      <origin
        xyz="0 0 0"
        rpy="0 0 0" />
      <geometry>
        <mesh
          filename="package://sixrobot_description/meshes/Link6.stl" />
      </geometry>
    </collision>
  </link>
  <joint
    name="joint6"
    type="continuous">
    <origin
      xyz="-0.13059 0 0.000625"
      rpy="0 0 0" />
    <parent
      link="Link5" />
    <child
      link="Link6" />
    <axis
      xyz="-1 0 0" />
  </joint>

  <link name="tool0"/>
  <joint name="joint_tool0" type="fixed">
    <origin xyz="-0.045 0.015 0" rpy="0 0 0" />
    <parent link="Link6" />
    <child link="tool0" />
  </joint>

   <!-- Attach the right gripper -->
   <gripper parent="tool0" color="Green" xyz="0 -0.015 0.01" rpy="0 0 ${M_PI}"/>

  <!-- Gazebo-Specific Link Properties -->
  <gazebo reference="world">
    <selfCollide>true</selfCollide>
    <material>Gazebo/White</material>
  </gazebo>
  <gazebo reference="base_link">
    <selfCollide>true</selfCollide>
    <material>Gazebo/White</material>
  </gazebo>

  <gazebo reference="Link1">
    <implicitSpringDamper>1</implicitSpringDamper>
    <material>Gazebo/Red</material>
  </gazebo>
  <gazebo reference="Link2">
    <implicitSpringDamper>1</implicitSpringDamper>
    <material>Gazebo/Green</material>
  </gazebo>
  <gazebo reference="Link3">
    <implicitSpringDamper>1</implicitSpringDamper>
    <material>Gazebo/Blue</material>
  </gazebo>
  <gazebo reference="Link4">
    <implicitSpringDamper>1</implicitSpringDamper>
    <material>Gazebo/Red</material>
  </gazebo>
  <gazebo reference="Link5">
    <implicitSpringDamper>1</implicitSpringDamper>
    <material>Gazebo/Green</material>
  </gazebo>
  <gazebo reference="Link6">
    <implicitSpringDamper>1</implicitSpringDamper>
    <material>Gazebo/Blue</material>
  </gazebo>
  <!-- Transmissions for ROS Control -->
  <xacro:macro name="transmission_block" params="joint_name">
    <transmission name="tran1">
      <type>transmission_interface/SimpleTransmission</type>
      <joint name="${joint_name}">
        <hardwareInterface>hardware_interface/PositionJointInterface</hardwareInterface>
      </joint>
      <actuator name="motor1">
        <hardwareInterface>hardware_interface/PositionJointInterface</hardwareInterface>
        <mechanicalReduction>1</mechanicalReduction>
      </actuator>
    </transmission>
  </xacro:macro>
  
  <xacro:transmission_block joint_name="joint1"/>
  <xacro:transmission_block joint_name="joint2"/>
  <xacro:transmission_block joint_name="joint3"/>
  <xacro:transmission_block joint_name="joint4"/>
  <xacro:transmission_block joint_name="joint5"/>
  <xacro:transmission_block joint_name="joint6"/>

  <xacro:transmission_block joint_name="gripper_finger_joint"/>

  <xacro:include filename="$(find sixrobot_description)/urdf/sensors/camera.urdf.xacro"/>

  <!-- ros_control plugin -->
  <gazebo>
    <plugin name="gazebo_ros_control" filename="libgazebo_ros_control.so">
      <robotNamespace>/sixrobot_anno</robotNamespace>
      <robotSimType>gazebo_ros_control/DefaultRobotHWSim</robotSimType>
      <legacyModeNS>true</legacyModeNS>
    </plugin>
  </gazebo>

</robot>
