<?xml version="1.0" ?>
<robot name="sixrobot" xmlns:xacro="http://www.ros.org/wiki/xacro">
  <xacro:arg name="gazebo" default="false"/>
  <xacro:if value="$(arg gazebo)">

    <!-- Gazebo Tags -->
    <xacro:include filename="$(find sixrobot_description)/urdf/xacro/gazebo/sixrobot_base_gazebo.xacro" />
  </xacro:if>
  <virtual_joint name="world_joint" type="fixed" parent_frame="world_frame" child_link="base_link" />
  <link name="world"/>
    
  <joint name="fixed" type="fixed">
  <parent link="world"/>
  <child link="base_link"/>
  </joint>
  <link
    name="base_link">
    <inertial>
      <origin
        xyz="-0.0075525 0.02417 0.018438"
        rpy="0 0 0" />
      <mass
        value="3.0395" />
      <inertia
        ixx="0.0025797"
        ixy="8.6805E-05"
        ixz="0.00017161"
        iyy="0.0014934"
        iyz="-0.00032354"
        izz="0.002124" />
    </inertial>
    <visual>
      <origin
        xyz="0 0 0"
        rpy="0 0 0" />
      <geometry>
        <mesh
          filename="package://sixrobot_description/meshes/base_link.stl" />
      </geometry>
      <material
        name="">
        <color
          rgba="255 250 250 1" />
      </material>
    </visual>
    <collision>
      <origin
        xyz="0 0 0"
        rpy="0 0 0" />
      <geometry>
        <mesh
          filename="package://sixrobot_description/meshes/base_link.stl" />
      </geometry>
    </collision>
  </link>
  <link
    name="Link1">
    <inertial>
      <origin
        xyz="-0.003411 0.071928 -0.0017952"
        rpy="0 0 0" />
      <mass
        value="3.1834" />
      <inertia
        ixx="0.0066967"
        ixy="0.00031535"
        ixz="-1.9127E-05"
        iyy="0.0018398"
        iyz="0.0002558"
        izz="0.0050889" />
    </inertial>
    <visual>
      <origin
        xyz="0 0 0"
        rpy="0 0 0" />
      <geometry>
        <mesh
          filename="package://sixrobot_description/meshes/Link1.stl" />
      </geometry>
      <material
        name="">
        <color
          rgba="255 0 0 1" />
      </material>
    </visual>
    <collision>
      <origin
        xyz="0 0 0"
        rpy="0 0 0" />
      <geometry>
        <mesh
          filename="package://sixrobot_description/meshes/Link1.stl" />
      </geometry>
    </collision>
  </link>
  <joint
    name="joint1"
    type="revolute">
    <origin
      xyz="-0.0088055 -0.022514 0.09434"
      rpy="1.5708 5.6825E-17 1.1891" />
    <parent
      link="base_link" />
    <child
      link="Link1" />
    <axis
      xyz="0 1 0" />
    <limit
      lower="-1.5708"
      upper="1.5708"
      effort="0"
      velocity="0" />
  </joint>
  <link
    name="Link2">
    <inertial>
      <origin
        xyz="0.14201 -8.8599E-08 -0.00098855"
        rpy="0 0 0" />
      <mass
        value="2.1027" />
      <inertia
        ixx="0.0029075"
        ixy="9.7718E-08"
        ixz="0.00037105"
        iyy="0.015387"
        iyz="-1.4864E-08"
        izz="0.012594" />
    </inertial>
    <visual>
      <origin
        xyz="0 0 0"
        rpy="0 0 0" />
      <geometry>
        <mesh
          filename="package://sixrobot_description/meshes/Link2.stl" />
      </geometry>
      <material
        name="">
        <color
          rgba="0 255 0 1" />
      </material>
    </visual>
    <collision>
      <origin
        xyz="0 0 0"
        rpy="0 0 0" />
      <geometry>
        <mesh
          filename="package://sixrobot_description/meshes/Link2.stl" />
      </geometry>
    </collision>
  </link>
  <joint
    name="joint2"
    type="revolute">
    <origin
      xyz="-0.005 0.1 0"
      rpy="3.1416 -1.1269E-15 1.5708" />
    <parent
      link="Link1" />
    <child
      link="Link2" />
    <axis
      xyz="0 0 -1" />
    <limit
      lower="-1.5708"
      upper="1.5708"
      effort="0"
      velocity="0" />
  </joint>
  <link
    name="Link3">
    <inertial>
      <origin
        xyz="-0.089574 0.0018335 0.00017688"
        rpy="0 0 0" />
      <mass
        value="1.9613" />
      <inertia
        ixx="0.0019119"
        ixy="5.1275E-05"
        ixz="-3.1104E-05"
        iyy="0.0043906"
        iyz="6.3374E-07"
        izz="0.0034664" />
    </inertial>
    <visual>
      <origin
        xyz="0 0 0"
        rpy="0 0 0" />
      <geometry>
        <mesh
          filename="package://sixrobot_description/meshes/Link3.stl" />
      </geometry>
      <material
        name="">
        <color
          rgba="0 0 255 1" />
      </material>
    </visual>
    <collision>
      <origin
        xyz="0 0 0"
        rpy="0 0 0" />
      <geometry>
        <mesh
          filename="package://sixrobot_description/meshes/Link3.stl" />
      </geometry>
    </collision>
  </link>
  <joint
    name="joint3"
    type="revolute">
    <origin
      xyz="0.205 0 0"
      rpy="-1.1102E-16 1.6099E-16 3.1416" />
    <parent
      link="Link2" />
    <child
      link="Link3" />
    <axis
      xyz="0 0 -1" />
    <limit
      lower="-1.5708"
      upper="1.5708"
      effort="0"
      velocity="0" />
  </joint>
  <link
    name="Link4">
    <inertial>
      <origin
        xyz="0.16649 0.021449 0.029405"
        rpy="0 0 0" />
      <mass
        value="1.7626" />
      <inertia
        ixx="0.00091529"
        ixy="-0.0006452"
        ixz="-0.00077218"
        iyy="0.0057445"
        iyz="-3.1391E-05"
        izz="0.0051203" />
    </inertial>
    <visual>
      <origin
        xyz="0 0 0"
        rpy="0 0 0" />
      <geometry>
        <mesh
          filename="package://sixrobot_description/meshes/Link4.stl" />
      </geometry>
      <material
        name="">
        <color
          rgba="255 0 0 1" />
      </material>
    </visual>
    <collision>
      <origin
        xyz="0 0 0"
        rpy="0 0 0" />
      <geometry>
        <mesh
          filename="package://sixrobot_description/meshes/Link4.stl" />
      </geometry>
    </collision>
  </link>
  <joint
    name="joint4"
    type="revolute">
    <origin
      xyz="-0.11 0 0"
      rpy="-0.13967 0.1538 1.4216" />
    <parent
      link="Link3" />
    <child
      link="Link4" />
    <axis
      xyz="0.97722 0.12611 0.17071" />
    <limit
      lower="-1.5708"
      upper="1.5708"
      effort="0"
      velocity="0" />
  </joint>
  <link
    name="Link5">
    <inertial>
      <origin
        xyz="-0.088587 5.3876E-09 0.00082307"
        rpy="0 0 0" />
      <mass
        value="1.9415" />
      <inertia
        ixx="0.0015409"
        ixy="7.8172E-09"
        ixz="-2.9862E-05"
        iyy="0.0044095"
        iyz="-8.3622E-08"
        izz="0.0033388" />
    </inertial>
    <visual>
      <origin
        xyz="0 0 0"
        rpy="0 0 0" />
      <geometry>
        <mesh
          filename="package://sixrobot_description/meshes/Link5.stl" />
      </geometry>
      <material
        name="">
        <color
          rgba="0 255 0 1" />
      </material>
    </visual>
    <collision>
      <origin
        xyz="0 0 0"
        rpy="0 0 0" />
      <geometry>
        <mesh
          filename="package://sixrobot_description/meshes/Link5.stl" />
      </geometry>
    </collision>
  </link>
  <joint
    name="joint5"
    type="revolute">
    <origin
      xyz="0.20277 0.026168 0.035423"
      rpy="-0.11711 0.17155 -3.0132" />
    <parent
      link="Link4" />
    <child
      link="Link5" />
    <axis
      xyz="0 0 -1" />
    <limit
      lower="-1.5708"
      upper="1.5708"
      effort="0"
      velocity="0" />
  </joint>
  <link
    name="Link6">
    <inertial>
      <origin
        xyz="-0.015821 9.9334E-07 -2.6332E-07"
        rpy="0 0 0" />
      <mass
        value="0.049116" />
      <inertia
        ixx="6.9904E-08"
        ixy="-6.6644E-10"
        ixz="1.7849E-10"
        iyy="6.1773E-07"
        iyz="4.2067E-13"
        izz="6.1773E-07" />
    </inertial>
    <visual>
      <origin
        xyz="0 0 0"
        rpy="0 0 0" />
      <geometry>
        <mesh
          filename="package://sixrobot_description/meshes/Link6.stl" />
      </geometry>
      <material
        name="">
        <color
          rgba="0 0 255 1" />
      </material>
    </visual>
    <collision>
      <origin
        xyz="0 0 0"
        rpy="0 0 0" />
      <geometry>
        <mesh
          filename="package://sixrobot_description/meshes/Link6.stl" />
      </geometry>
    </collision>
  </link>
  <joint
    name="joint6"
    type="continuous">
    <origin
      xyz="-0.13508 0 0.000625"
      rpy="-1.8616 -2.3315E-15 8.5363E-18" />
    <parent
      link="Link5" />
    <child
      link="Link6" />
    <axis
      xyz="-1 0 0" />
  </joint>
</robot>
